# Routersploit-Exploit-IP-error

Traceback (most recent call last):
  File "/data/data/com.termux/files/home/routersploit/routersploit/core/exploit/utils.py", line 109, in import_exploit
    module = importlib.import_module(path)
  File "/data/data/com.termux/files/usr/lib/python3.10/importlib/__init__.py", line 126, in import_module
    return _bootstrap._gcd_import(name[level:], package, level)
  File "<frozen importlib._bootstrap>", line 1050, in _gcd_import
  File "<frozen importlib._bootstrap>", line 1027, in _find_and_load
  File "<frozen importlib._bootstrap>", line 1006, in _find_and_load_unlocked
  File "<frozen importlib._bootstrap>", line 688, in _load_unlocked
  File "<frozen importlib._bootstrap_external>", line 883, in exec_module
  File "<frozen importlib._bootstrap>", line 241, in _call_with_frames_removed
  File "/data/data/com.termux/files/home/routersploit/routersploit/modules/exploits/generic/heartbleed.py", line 5, in <module>
    from cryptography import x509
ModuleNotFoundError: No module named 'cryptography'

During handling of the above exception, another exception occurred:

Traceback (most recent call last):
  File "/data/data/com.termux/files/home/routersploit/routersploit/interpreter.py", line 389, in command_run
    self.current_module.run()
  File "/data/data/com.termux/files/home/routersploit/routersploit/modules/scanners/autopwn.py", line 77, in run
    for module in utils.iter_modules(directory):
  File "/data/data/com.termux/files/home/routersploit/routersploit/core/exploit/utils.py", line 138, in iter_modules
    yield import_exploit(path)
  File "/data/data/com.termux/files/home/routersploit/routersploit/core/exploit/utils.py", line 120, in import_exploit
    raise RoutersploitException(
routersploit.core.exploit.exceptions.RoutersploitException: Error during loading 'routersploit/modules/exploits/generic/heartbleed'

Error: No module named 'cryptography'

It should be valid path to the module. Use <tab> key multiple times for completion.

During handling of the above exception, another exception occurred:

Traceback (most recent call last):
  File "/data/data/com.termux/files/home/routersploit/rsf.py", line 29, in <module>
    routersploit(sys.argv)
  File "/data/data/com.termux/files/home/routersploit/rsf.py", line 25, in routersploit
    rsf.start()
  File "/data/data/com.termux/files/home/routersploit/routersploit/interpreter.py", line 125, in start
    command_handler(args, **kwargs)
  File "/data/data/com.termux/files/home/routersploit/routersploit/interpreter.py", line 397, in command_exploit
    self.command_run()
  File "/data/data/com.termux/files/home/routersploit/routersploit/core/exploit/utils.py", line 177, in wrapper
    return fn(self, *args, **kwargs)
  File "/data/data/com.termux/files/home/routersploit/routersploit/interpreter.py", line 394, in command_run
    print_error(traceback.format_exc(sys.exc_info()))
  File "/data/data/com.termux/files/usr/lib/python3.10/traceback.py", line 183, in format_exc
    return "".join(format_exception(*sys.exc_info(), limit=limit, chain=chain))
  File "/data/data/com.termux/files/usr/lib/python3.10/traceback.py", line 135, in format_exception
    te = TracebackException(type(value), value, tb, limit=limit, compact=True)
  File "/data/data/com.termux/files/usr/lib/python3.10/traceback.py", line 502, in __init__
    self.stack = StackSummary.extract(
  File "/data/data/com.termux/files/usr/lib/python3.10/traceback.py", line 357, in extract
    if limit >= 0:
TypeError: '>=' not supported between instances of 'tuple' and 'in
